<?xml version="1.0" encoding="utf-8"?>
<!-- This URDF was automatically created by SolidWorks to URDF Exporter! Originally created by Stephen Brawner (brawner@gmail.com) 
     Commit Version: 1.6.0-1-g15f4949  Build Version: 1.6.7594.29634
     For more information, please see http://wiki.ros.org/sw_urdf_exporter -->
<robot
  name="hangcha_chassis">
  <link
    name="base_link">
    <inertial>
      <origin
        xyz="-0.0484690094575794 0.0491514374755153 0.192635133161548"
        rpy="0 0 0" />
      <mass
        value="713.853630506361" />
      <inertia
        ixx="123.138959258322"
        ixy="-2.3795730152606"
        ixz="0.000712574319530658"
        iyy="146.725736238224"
        iyz="0.00013776173902626"
        izz="239.820126084134" />
    </inertial>
    <visual>
      <origin
        xyz="0 0 0"
        rpy="0 0 0" />
      <geometry>
        <mesh
          filename="package://hangcha_chassis/meshes/base_link.STL" />
      </geometry>
      <material
        name="">
        <color
          rgba="0.796078431372549 0.823529411764706 0.933333333333333 1" />
      </material>
    </visual>
    <collision>
      <origin
        xyz="0 0 0"
        rpy="0 0 0" />
      <geometry>
        <mesh
          filename="package://hangcha_chassis/meshes/base_link.STL" />
      </geometry>
    </collision>
  </link>
  <link
    name="front_right_link">
    <inertial>
      <origin
        xyz="-1.6659 0.84068 1.2521"
        rpy="0 0 0" />
      <mass
        value="2090.5" />
      <inertia
        ixx="2834.2"
        ixy="135.58"
        ixz="-412.13"
        iyy="4339.4"
        iyz="795.13"
        izz="3274.2" />
    </inertial>
    <visual>
      <origin
        xyz="0 0 0"
        rpy="0 0 0" />
      <geometry>
        <mesh
          filename="package://hangcha_chassis/meshes/front_right_link.STL" />
      </geometry>
      <material
        name="">
        <color
          rgba="0.79608 0.82353 0.93333 1" />
      </material>
    </visual>
    <collision>
      <origin
        xyz="0 0 0"
        rpy="0 0 0" />
      <geometry>
        <mesh
          filename="package://hangcha_chassis/meshes/front_right_link.STL" />
      </geometry>
    </collision>
  </link>
  <joint
    name="front_right_joint"
    type="continuous">
    <origin
      xyz="1.251 -0.99275 -0.47949"
      rpy="0 0 0" />
    <parent
      link="base_link" />
    <child
      link="front_right_link" />
    <axis
      xyz="0 1 -1.0507E-05" />
  </joint>
  <link
    name="front_left_link">
    <inertial>
      <origin
        xyz="-1.6659 -1.1448 1.2521"
        rpy="0 0 0" />
      <mass
        value="2090.5" />
      <inertia
        ixx="2834.2"
        ixy="135.58"
        ixz="-412.13"
        iyy="4339.4"
        iyz="795.13"
        izz="3274.2" />
    </inertial>
    <visual>
      <origin
        xyz="0 0 0"
        rpy="0 0 0" />
      <geometry>
        <mesh
          filename="package://hangcha_chassis/meshes/front_left_link.STL" />
      </geometry>
      <material
        name="">
        <color
          rgba="0.79608 0.82353 0.93333 1" />
      </material>
    </visual>
    <collision>
      <origin
        xyz="0 0 0"
        rpy="0 0 0" />
      <geometry>
        <mesh
          filename="package://hangcha_chassis/meshes/front_left_link.STL" />
      </geometry>
    </collision>
  </link>
  <joint
    name="front_left_joint"
    type="continuous">
    <origin
      xyz="1.251 0.99275 -0.47951"
      rpy="0 0 0" />
    <parent
      link="base_link" />
    <child
      link="front_left_link" />
    <axis
      xyz="0 -1 1.0507E-05" />
  </joint>
  <link
    name="back_left_link">
    <inertial>
      <origin
        xyz="0.83511 -1.1348 1.2611"
        rpy="0 0 0" />
      <mass
        value="2090.5" />
      <inertia
        ixx="2834.2"
        ixy="135.58"
        ixz="-412.13"
        iyy="4339.4"
        iyz="795.13"
        izz="3274.2" />
    </inertial>
    <visual>
      <origin
        xyz="0 0 0"
        rpy="0 0 0" />
      <geometry>
        <mesh
          filename="package://hangcha_chassis/meshes/back_left_link.STL" />
      </geometry>
      <material
        name="">
        <color
          rgba="0.79608 0.82353 0.93333 1" />
      </material>
    </visual>
    <collision>
      <origin
        xyz="0 0 0"
        rpy="0 0 0" />
      <geometry>
        <mesh
          filename="package://hangcha_chassis/meshes/back_left_link.STL" />
      </geometry>
    </collision>
  </link>
  <joint
    name="back_left_joint"
    type="continuous">
    <origin
      xyz="-1.25 0.98275 -0.4885"
      rpy="0 0 0" />
    <parent
      link="base_link" />
    <child
      link="back_left_link" />
    <axis
      xyz="0 -1 0" />
  </joint>
  <link
    name="back_right_link">
    <inertial>
      <origin
        xyz="0.83511 0.84068 1.2611"
        rpy="0 0 0" />
      <mass
        value="2090.5" />
      <inertia
        ixx="2834.2"
        ixy="135.58"
        ixz="-412.13"
        iyy="4339.4"
        iyz="795.13"
        izz="3274.2" />
    </inertial>
    <visual>
      <origin
        xyz="0 0 0"
        rpy="0 0 0" />
      <geometry>
        <mesh
          filename="package://hangcha_chassis/meshes/back_right_link.STL" />
      </geometry>
      <material
        name="">
        <color
          rgba="0.79608 0.82353 0.93333 1" />
      </material>
    </visual>
    <collision>
      <origin
        xyz="0 0 0"
        rpy="0 0 0" />
      <geometry>
        <mesh
          filename="package://hangcha_chassis/meshes/back_right_link.STL" />
      </geometry>
    </collision>
  </link>
  <joint
    name="back_right_joint"
    type="continuous">
    <origin
      xyz="-1.25 -0.99275 -0.4885"
      rpy="0 0 0" />
    <parent
      link="base_link" />
    <child
      link="back_right_link" />
    <axis
      xyz="0 1 0" />
  </joint>
</robot>