<?xml version="1.0" encoding="utf-8"?>
<!-- This URDF was automatically created by SolidWorks to URDF Exporter! Originally created by Stephen Brawner (brawner@gmail.com) 
     Commit Version: 1.6.0-1-g15f4949  Build Version: 1.6.7594.29634
     For more information, please see http://wiki.ros.org/sw_urdf_exporter -->
<robot
  name="kr_210_r3100-2_v02">
  <link
    name="base_link">
    <inertial>
      <origin
        xyz="-0.10967 -0.0017375 0.10512"
        rpy="0 0 0" />
      <mass
        value="69.137" />
      <inertia
        ixx="1.5959"
        ixy="0.0085691"
        ixz="0.36741"
        iyy="3.5005"
        iyz="-0.0020918"
        izz="4.2719" />
    </inertial>
    <visual>
      <origin
        xyz="0 0 0"
        rpy="0 0 0" />
      <geometry>
        <mesh
          filename="package://kr_210_r3100-2_v02/meshes/base_link.STL" />
      </geometry>
      <material
        name="">
        <color
          rgba="0.4 0.4 0.4 1" />
      </material>
    </visual>
    <collision>
      <origin
        xyz="0 0 0"
        rpy="0 0 0" />
      <geometry>
        <mesh
          filename="package://kr_210_r3100-2_v02/meshes/base_link.STL" />
      </geometry>
    </collision>
  </link>
  <link
    name="link_1">
    <inertial>
      <origin
        xyz="0.32903 0.12615 0.4094"
        rpy="0 0 0" />
      <mass
        value="6.8182" />
      <inertia
        ixx="0.04654"
        ixy="0.00044646"
        ixz="1.3773E-08"
        iyy="0.03178"
        iyz="5.6574E-08"
        izz="0.04705" />
    </inertial>
    <visual>
      <origin
        xyz="0 0 0"
        rpy="0 0 0" />
      <geometry>
        <mesh
          filename="package://kr_210_r3100-2_v02/meshes/link_1.STL" />
      </geometry>
      <material
        name="">
        <color
          rgba="0.4 0.4 0.4 1" />
      </material>
    </visual>
    <collision>
      <origin
        xyz="0 0 0"
        rpy="0 0 0" />
      <geometry>
        <mesh
          filename="package://kr_210_r3100-2_v02/meshes/link_1.STL" />
      </geometry>
    </collision>
  </link>
  <joint
    name="joint_a1"
    type="revolute">
    <origin
      xyz="0.0061558 0 0.2256"
      rpy="0 0 0" />
    <parent
      link="base_link" />
    <child
      link="link_1" />
    <axis
      xyz="0 0 1" />
    <limit
      lower="-3.14"
      upper="3.14"
      effort="0"
      velocity="0" />
  </joint>
  <link
    name="link_2">
    <inertial>
      <origin
        xyz="0.53587 0.001548 -0.24013"
        rpy="0 0 0" />
      <mass
        value="98.626" />
      <inertia
        ixx="1.6623"
        ixy="0.091397"
        ixz="1.4945"
        iyy="25.464"
        iyz="0.0013736"
        izz="25.241" />
    </inertial>
    <visual>
      <origin
        xyz="0 0 0"
        rpy="0 0 0" />
      <geometry>
        <mesh
          filename="package://kr_210_r3100-2_v02/meshes/link_2.STL" />
      </geometry>
      <material
        name="">
        <color
          rgba="0.4 0.4 0.4 1" />
      </material>
    </visual>
    <collision>
      <origin
        xyz="0 0 0"
        rpy="0 0 0" />
      <geometry>
        <mesh
          filename="package://kr_210_r3100-2_v02/meshes/link_2.STL" />
      </geometry>
    </collision>
  </link>
  <joint
    name="joint_a2"
    type="revolute">
    <origin
      xyz="0.33002 0.0090001 0.40937"
      rpy="-1.5708 0 0" />
    <parent
      link="link_1" />
    <child
      link="link_2" />
    <axis
      xyz="0 0 1" />
    <limit
      lower="-3.14"
      upper="3.14"
      effort="0"
      velocity="0" />
  </joint>
  <link
    name="link_3">
    <inertial>
      <origin
        xyz="0.0802900117763414 -0.125478502915676 0.0907889541263482"
        rpy="0 0 0" />
      <mass
        value="13.1780351288155" />
      <inertia
        ixx="0.087771211337227"
        ixy="-0.000202004164649328"
        ixz="0.00044198584868771"
        iyy="0.0595564700843223"
        iyz="-5.13805553066225E-06"
        izz="0.0731652127601232" />
    </inertial>
    <visual>
      <origin
        xyz="0 0 0"
        rpy="0 0 0" />
      <geometry>
        <mesh
          filename="package://kr_210_r3100-2_v02/meshes/link_3.STL" />
      </geometry>
      <material
        name="">
        <color
          rgba="0.4 0.4 0.4 1" />
      </material>
    </visual>
    <collision>
      <origin
        xyz="0 0 0"
        rpy="0 0 0" />
      <geometry>
        <mesh
          filename="package://kr_210_r3100-2_v02/meshes/link_3.STL" />
      </geometry>
    </collision>
  </link>
  <joint
    name="joint_a3"
    type="revolute">
    <origin
      xyz="1.35 -2.8782E-05 -0.071"
      rpy="0 0 -1.5708" />
    <parent
      link="link_2" />
    <child
      link="link_3" />
    <axis
      xyz="0 0 1" />
    <limit
      lower="-3.14"
      upper="3.14"
      effort="0"
      velocity="0" />
  </joint>
  <link
    name="link_4">
    <inertial>
      <origin
        xyz="-6.572E-06 -0.0044926 0.18467"
        rpy="0 0 0" />
      <mass
        value="5.0535" />
      <inertia
        ixx="0.088804"
        ixy="8.9573E-07"
        ixz="-2.0216E-06"
        iyy="0.089166"
        iyz="0.0040501"
        izz="0.012447" />
    </inertial>
    <visual>
      <origin
        xyz="0 0 0"
        rpy="0 0 0" />
      <geometry>
        <mesh
          filename="package://kr_210_r3100-2_v02/meshes/link_4.STL" />
      </geometry>
      <material
        name="">
        <color
          rgba="0.4 0.4 0.4 1" />
      </material>
    </visual>
    <collision>
      <origin
        xyz="0 0 0"
        rpy="0 0 0" />
      <geometry>
        <mesh
          filename="package://kr_210_r3100-2_v02/meshes/link_4.STL" />
      </geometry>
    </collision>
  </link>
  <joint
    name="joint_a4"
    type="revolute">
    <origin
      xyz="0.115 1.0685 0.062"
      rpy="-1.5708 0 0" />
    <parent
      link="link_3" />
    <child
      link="link_4" />
    <axis
      xyz="0 0 -1" />
    <limit
      lower="-3.14"
      upper="3.14"
      effort="0"
      velocity="0" />
  </joint>
  <link
    name="link_5">
    <inertial>
      <origin
        xyz="-6.0688E-05 0.057604 -0.012629"
        rpy="0 0 0" />
      <mass
        value="10.003" />
      <inertia
        ixx="0.14296"
        ixy="3.1916E-05"
        ixz="1.1873E-05"
        iyy="0.098519"
        iyz="0.029393"
        izz="0.10143" />
    </inertial>
    <visual>
      <origin
        xyz="0 0 0"
        rpy="0 0 0" />
      <geometry>
        <mesh
          filename="package://kr_210_r3100-2_v02/meshes/link_5.STL" />
      </geometry>
      <material
        name="">
        <color
          rgba="0.4 0.4 0.4 1" />
      </material>
    </visual>
    <collision>
      <origin
        xyz="0 0 0"
        rpy="0 0 0" />
      <geometry>
        <mesh
          filename="package://kr_210_r3100-2_v02/meshes/link_5.STL" />
      </geometry>
    </collision>
  </link>
  <joint
    name="joint_a5"
    type="revolute">
    <origin
      xyz="3.2106E-05 -0.059 0.35153"
      rpy="1.5708 0 0" />
    <parent
      link="link_4" />
    <child
      link="link_5" />
    <axis
      xyz="0 0 -1" />
    <limit
      lower="-3.14"
      upper="3.14"
      effort="0"
      velocity="0" />
  </joint>
  <link
    name="link_6">
    <inertial>
      <origin
        xyz="1.3996E-05 -5.1777E-05 0.021694"
        rpy="0 0 0" />
      <mass
        value="0.83898" />
      <inertia
        ixx="0.0021717"
        ixy="5.9101E-08"
        ixz="1.2263E-07"
        iyy="0.0021671"
        iyz="1.2468E-07"
        izz="0.0041792" />
    </inertial>
    <visual>
      <origin
        xyz="0 0 0"
        rpy="0 0 0" />
      <geometry>
        <mesh
          filename="package://kr_210_r3100-2_v02/meshes/link_6.STL" />
      </geometry>
      <material
        name="">
        <color
          rgba="0.4 0.4 0.4 1" />
      </material>
    </visual>
    <collision>
      <origin
        xyz="0 0 0"
        rpy="0 0 0" />
      <geometry>
        <mesh
          filename="package://kr_210_r3100-2_v02/meshes/link_6.STL" />
      </geometry>
    </collision>
  </link>
  <joint
    name="joint_a6"
    type="revolute">
    <origin
      xyz="-3.2106E-05 0.20007 -0.059"
      rpy="-1.5708 0 0" />
    <parent
      link="link_5" />
    <child
      link="link_6" />
    <axis
      xyz="0 0 -1" />
    <limit
      lower="-3.14"
      upper="3.14"
      effort="0"
      velocity="0" />
  </joint>
</robot>
